<?xml version="1.0" ?>
<!-- =================================================================================== -->
<!-- |    This document was autogenerated by xacro from src/shrimp_modu/urdf/shrimp.urdf.xacro | -->
<!-- |    EDITING THIS FILE BY HAND IS NOT RECOMMENDED                                 | -->
<!-- =================================================================================== -->
<robot name="shrimp">
  <!-- ================= PARAMETERS ================= -->
  <!-- ================= MATERIALS ================= -->
  <material name="chassis_blue">
    <color rgba="0 0 1 1"/>
  </material>
  <material name="wheel_red">
    <color rgba="1 0 0 1"/>
  </material>
  <!-- ================= BASE LINK ================= -->
  <link name="base_link">
    <visual>
      <geometry>
        <box size="0.25 0.20384 0.15"/>
      </geometry>
      <material name="chassis_blue"/>
    </visual>
  </link>
  <!-- ================= WHEEL MACRO ================= -->
  <!-- ================= LEFT WHEELS ================= -->
  <link name="front_left_wheel">
    <visual>
      <geometry>
        <cylinder length="0.056" radius="0.0585"/>
      </geometry>
      <material name="wheel_red"/>
    </visual>
  </link>
  <joint name="front_left_wheel_joint" type="continuous">
    <parent link="base_link"/>
    <child link="front_left_wheel"/>
    <origin rpy="0 1.5708 0" xyz="0.085 0.094775 -0.10417"/>
    <axis xyz="0 1 0"/>
  </joint>
  <link name="middle_left_wheel">
    <visual>
      <geometry>
        <cylinder length="0.056" radius="0.0585"/>
      </geometry>
      <material name="wheel_red"/>
    </visual>
  </link>
  <joint name="middle_left_wheel_joint" type="continuous">
    <parent link="base_link"/>
    <child link="middle_left_wheel"/>
    <origin rpy="0 1.5708 0" xyz="0.0 0.094775 -0.10417"/>
    <axis xyz="0 1 0"/>
  </joint>
  <link name="rear_left_wheel">
    <visual>
      <geometry>
        <cylinder length="0.056" radius="0.0585"/>
      </geometry>
      <material name="wheel_red"/>
    </visual>
  </link>
  <joint name="rear_left_wheel_joint" type="continuous">
    <parent link="base_link"/>
    <child link="rear_left_wheel"/>
    <origin rpy="0 1.5708 0" xyz="-0.085 0.094775 -0.10417"/>
    <axis xyz="0 1 0"/>
  </joint>
  <!-- ================= RIGHT WHEELS ================= -->
  <link name="front_right_wheel">
    <visual>
      <geometry>
        <cylinder length="0.056" radius="0.0585"/>
      </geometry>
      <material name="wheel_red"/>
    </visual>
  </link>
  <joint name="front_right_wheel_joint" type="continuous">
    <parent link="base_link"/>
    <child link="front_right_wheel"/>
    <origin rpy="0 1.5708 0" xyz="0.085 -0.094775 -0.10417"/>
    <axis xyz="0 1 0"/>
  </joint>
  <link name="middle_right_wheel">
    <visual>
      <geometry>
        <cylinder length="0.056" radius="0.0585"/>
      </geometry>
      <material name="wheel_red"/>
    </visual>
  </link>
  <joint name="middle_right_wheel_joint" type="continuous">
    <parent link="base_link"/>
    <child link="middle_right_wheel"/>
    <origin rpy="0 1.5708 0" xyz="0.0 -0.094775 -0.10417"/>
    <axis xyz="0 1 0"/>
  </joint>
  <link name="rear_right_wheel">
    <visual>
      <geometry>
        <cylinder length="0.056" radius="0.0585"/>
      </geometry>
      <material name="wheel_red"/>
    </visual>
  </link>
  <joint name="rear_right_wheel_joint" type="continuous">
    <parent link="base_link"/>
    <child link="rear_right_wheel"/>
    <origin rpy="0 1.5708 0" xyz="-0.085 -0.094775 -0.10417"/>
    <axis xyz="0 1 0"/>
  </joint>
</robot>
